<?xml version="1.0"?>
<robot xmlns:xacro="http://wiki.ros.org/xacro">

  <xacro:macro name="wheel" params="side wheel_radius x y">

    <xacro:property name="wheel_thickness" value="0.031" />
    <xacro:property name="wheel_mass" value="0.4" />

    <joint name="${side}_wheel_joint" type="continuous">
      <parent link="body_link" />
      <child link="${side}_wheel_link" />
      <origin xyz="${x} ${y} 0.0" rpy="0.0 0.0 0.0" />
      <axis xyz="0.0 1.0 0.0" />
      <limit effort="1.5" velocity="30.0" />
      <dynamics damping="0.001" friction="0.001" />
    </joint>

    <link name="${side}_wheel_link">
      <visual>
      <geometry>
        <mesh filename="package://sar_description/meshes/wheel.dae"
              scale="0.0011 0.0011 0.0011"/>
      </geometry>
        <origin xyz="-0.07 -0.015 -0.022" rpy="0.0 0.0 ${pi/2}" />
        <material name="wheel_color">
          <color rgba="0.1 0.1 0.1 1.0" />
        </material>
      </visual>

      <collision>
        <geometry>
          <cylinder radius="${wheel_radius}" length="${wheel_thickness}" />
        </geometry>
        <origin xyz="0.0 0.0 0.0" rpy="${pi/2} 0.0 0.0" />
      </collision>

      <inertial>
        <mass value="${wheel_mass}" />
        <inertia ixx="0.000228454" ixy="-0.000015215" ixz="-0.000043405"
                                  iyy="0.000209819" iyz="-0.000066187"
                                                   izz="0.000044202" />
      </inertial>
    </link>

  </xacro:macro>

</robot>
